Rasa process starting
Rasa process starting
Restoring parameters from models/nlu/default/Banking_bot/intent_classifier_tensorflow_embedding.ckpt
Restoring parameters from models/dialogue/policy_1_EmbeddingPolicy/tensorflow_embedding.ckpt
Available web server routes: 
static                                             OPTIONS, GET, HEAD             /static/[filename]
custom_webhook_CmdlineInput.health                 OPTIONS, GET, HEAD             /webhooks/rest/
custom_webhook_CmdlineInput.receive                OPTIONS, POST                  /webhooks/rest/webhook
Rasa Core server is up and running on http://localhost:5005
Creating a new tracker for id 'default'.
Received user message 'hi there' with intent '{'name': 'greet', 'confidence': 0.979777455329895}' and entities '[]'
Logged UserUtterance - tracker now has 2 events
Current slot values: 

Current tracker state [None, None, None, {}, {'prev_action_listen': 1.0, 'intent_greet': 1.0}]
There is a memorised next action '7'
Predicted next action using policy_0_MemoizationPolicy
Predicted next action 'utter_greet' with prob 1.00.
Action 'utter_greet' ended with events '[]'
Bot utterance 'BotUttered(text: Hello! How can i help?, data: {
  "elements": null,
  "buttons": null,
  "attachment": null
})'
Current tracker state [None, None, {}, {'prev_action_listen': 1.0, 'intent_greet': 1.0}, {'prev_utter_greet': 1.0, 'intent_greet': 1.0}]
There is a memorised next action '0'
Predicted next action using policy_0_MemoizationPolicy
Predicted next action 'action_listen' with prob 1.00.
Action 'action_listen' ended with events '[]'
Recreating tracker for id 'default'
Received user message 'can i get any loan?' with intent '{'name': 'ask_faq_loan', 'confidence': 0.8919856548309326}' and entities '[]'
Logged UserUtterance - tracker now has 6 events
Current slot values: 

Current tracker state [None, {}, {'prev_action_listen': 1.0, 'intent_greet': 1.0}, {'prev_utter_greet': 1.0, 'intent_greet': 1.0}, {'prev_action_listen': 1.0, 'intent_ask_faq_loan': 1.0}]
There is no memorised next action
Feature 'intent_ask_faq_loan' could not be found in feature map.
Predicted next action using policy_1_EmbeddingPolicy
Predicted next action 'utter_greet' with prob 1.00.
Action 'utter_greet' ended with events '[]'
Bot utterance 'BotUttered(text: Hello! How can i help?, data: {
  "elements": null,
  "buttons": null,
  "attachment": null
})'
Current tracker state [{}, {'prev_action_listen': 1.0, 'intent_greet': 1.0}, {'prev_utter_greet': 1.0, 'intent_greet': 1.0}, {'prev_action_listen': 1.0, 'intent_ask_faq_loan': 1.0}, {'prev_utter_greet': 1.0, 'intent_ask_faq_loan': 1.0}]
There is no memorised next action
Feature 'intent_ask_faq_loan' could not be found in feature map.
Feature 'intent_ask_faq_loan' could not be found in feature map.
Predicted next action using policy_1_EmbeddingPolicy
Predicted next action 'action_listen' with prob 0.60.
Action 'action_listen' ended with events '[]'
Rasa process starting
Restoring parameters from models/nlu/default/Banking_bot/intent_classifier_tensorflow_embedding.ckpt
Available web server routes: 
static                                             OPTIONS, HEAD, GET             /static/[filename]
custom_webhook_CmdlineInput.health                 OPTIONS, HEAD, GET             /webhooks/rest/
custom_webhook_CmdlineInput.receive                POST, OPTIONS                  /webhooks/rest/webhook
Rasa Core server is up and running on http://localhost:5005
Creating a new tracker for id 'default'.
Received user message 'can i get any loan?' with intent '{'name': 'ask_faq_loan', 'confidence': 0.8919856548309326}' and entities '[]'
Logged UserUtterance - tracker now has 2 events
Current slot values: 

Current tracker state [None, None, None, {}, {'intent_ask_faq_loan': 1.0, 'prev_action_listen': 1.0}]
There is no memorised next action
Feature 'intent_ask_faq_loan' (value: '1.0') could not be found in feature map. Make sure you added all intents and entities to the domain
Predicted next action using policy_1_KerasPolicy
Predicted next action 'action_faqs' with prob 0.72.
Encountered an exception while running action 'action_faqs'. Bot will continue, but the actions events are lost. Make sure to fix the exception in your custom code.
The model predicted the custom action 'action_faqs' but you didn't configure an endpoint to run this custom action. Please take a look at the docs and set an endpoint configuration. https://rasa.com/docs/core/customactions/
Traceback (most recent call last):
  File "/home/omega/anaconda3/lib/python3.6/site-packages/rasa_core/processor.py", line 346, in _run_action
    events = action.run(dispatcher, tracker, self.domain)
  File "/home/omega/anaconda3/lib/python3.6/site-packages/rasa_core/actions/action.py", line 325, in run
    "".format(self.name(), DOCS_BASE_URL))
Exception: The model predicted the custom action 'action_faqs' but you didn't configure an endpoint to run this custom action. Please take a look at the docs and set an endpoint configuration. https://rasa.com/docs/core/customactions/
Action 'action_faqs' ended with events '[]'
Current tracker state [None, None, {}, {'intent_ask_faq_loan': 1.0, 'prev_action_listen': 1.0}, {'prev_action_faqs': 1.0, 'intent_ask_faq_loan': 1.0}]
There is no memorised next action
Feature 'intent_ask_faq_loan' (value: '1.0') could not be found in feature map. Make sure you added all intents and entities to the domain
Feature 'intent_ask_faq_loan' (value: '1.0') could not be found in feature map. Make sure you added all intents and entities to the domain
Predicted next action using policy_1_KerasPolicy
Predicted next action 'action_listen' with prob 0.98.
Action 'action_listen' ended with events '[]'
Recreating tracker for id 'default'
Received user message 'what is the procedure for car loan?' with intent '{'name': 'ask_faq_car_loan', 'confidence': 0.8091707229614258}' and entities '[]'
Logged UserUtterance - tracker now has 5 events
Current slot values: 

Current tracker state [None, {}, {'intent_ask_faq_loan': 1.0, 'prev_action_listen': 1.0}, {'prev_action_faqs': 1.0, 'intent_ask_faq_loan': 1.0}, {'intent_ask_faq_car_loan': 1.0, 'prev_action_listen': 1.0}]
There is no memorised next action
Feature 'intent_ask_faq_loan' (value: '1.0') could not be found in feature map. Make sure you added all intents and entities to the domain
Feature 'intent_ask_faq_loan' (value: '1.0') could not be found in feature map. Make sure you added all intents and entities to the domain
Feature 'intent_ask_faq_car_loan' (value: '1.0') could not be found in feature map. Make sure you added all intents and entities to the domain
Predicted next action using policy_1_KerasPolicy
Predicted next action 'action_faqs' with prob 0.80.
Encountered an exception while running action 'action_faqs'. Bot will continue, but the actions events are lost. Make sure to fix the exception in your custom code.
The model predicted the custom action 'action_faqs' but you didn't configure an endpoint to run this custom action. Please take a look at the docs and set an endpoint configuration. https://rasa.com/docs/core/customactions/
Traceback (most recent call last):
  File "/home/omega/anaconda3/lib/python3.6/site-packages/rasa_core/processor.py", line 346, in _run_action
    events = action.run(dispatcher, tracker, self.domain)
  File "/home/omega/anaconda3/lib/python3.6/site-packages/rasa_core/actions/action.py", line 325, in run
    "".format(self.name(), DOCS_BASE_URL))
Exception: The model predicted the custom action 'action_faqs' but you didn't configure an endpoint to run this custom action. Please take a look at the docs and set an endpoint configuration. https://rasa.com/docs/core/customactions/
Action 'action_faqs' ended with events '[]'
Current tracker state [{}, {'intent_ask_faq_loan': 1.0, 'prev_action_listen': 1.0}, {'prev_action_faqs': 1.0, 'intent_ask_faq_loan': 1.0}, {'intent_ask_faq_car_loan': 1.0, 'prev_action_listen': 1.0}, {'prev_action_faqs': 1.0, 'intent_ask_faq_car_loan': 1.0}]
There is no memorised next action
Feature 'intent_ask_faq_loan' (value: '1.0') could not be found in feature map. Make sure you added all intents and entities to the domain
Feature 'intent_ask_faq_car_loan' (value: '1.0') could not be found in feature map. Make sure you added all intents and entities to the domain
Feature 'intent_ask_faq_car_loan' (value: '1.0') could not be found in feature map. Make sure you added all intents and entities to the domain
Predicted next action using policy_1_KerasPolicy
Predicted next action 'action_listen' with prob 0.99.
Action 'action_listen' ended with events '[]'
Rasa process starting
Restoring parameters from models/nlu/default/Banking_bot/intent_classifier_tensorflow_embedding.ckpt
Available web server routes: 
static                                             HEAD, GET, OPTIONS             /static/[filename]
custom_webhook_CmdlineInput.health                 HEAD, GET, OPTIONS             /webhooks/rest/
custom_webhook_CmdlineInput.receive                POST, OPTIONS                  /webhooks/rest/webhook
Rasa Core server is up and running on http://localhost:5005
Creating a new tracker for id 'default'.
Received user message 'can i take any loan?' with intent '{'name': 'ask_faq_loan', 'confidence': 0.9547288417816162}' and entities '[]'
Logged UserUtterance - tracker now has 2 events
Current slot values: 

Current tracker state [None, None, None, {}, {'prev_action_listen': 1.0, 'intent_ask_faq_loan': 1.0}]
There is no memorised next action
Feature 'intent_ask_faq_loan' (value: '1.0') could not be found in feature map. Make sure you added all intents and entities to the domain
Predicted next action using policy_1_KerasPolicy
Predicted next action 'action_faqs' with prob 0.72.
Encountered an exception while running action 'action_faqs'. Bot will continue, but the actions events are lost. Make sure to fix the exception in your custom code.
The model predicted the custom action 'action_faqs' but you didn't configure an endpoint to run this custom action. Please take a look at the docs and set an endpoint configuration. https://rasa.com/docs/core/customactions/
Traceback (most recent call last):
  File "/home/omega/anaconda3/lib/python3.6/site-packages/rasa_core/processor.py", line 346, in _run_action
    events = action.run(dispatcher, tracker, self.domain)
  File "/home/omega/anaconda3/lib/python3.6/site-packages/rasa_core/actions/action.py", line 325, in run
    "".format(self.name(), DOCS_BASE_URL))
Exception: The model predicted the custom action 'action_faqs' but you didn't configure an endpoint to run this custom action. Please take a look at the docs and set an endpoint configuration. https://rasa.com/docs/core/customactions/
Action 'action_faqs' ended with events '[]'
Current tracker state [None, None, {}, {'prev_action_listen': 1.0, 'intent_ask_faq_loan': 1.0}, {'prev_action_faqs': 1.0, 'intent_ask_faq_loan': 1.0}]
There is no memorised next action
Feature 'intent_ask_faq_loan' (value: '1.0') could not be found in feature map. Make sure you added all intents and entities to the domain
Feature 'intent_ask_faq_loan' (value: '1.0') could not be found in feature map. Make sure you added all intents and entities to the domain
Predicted next action using policy_1_KerasPolicy
Predicted next action 'action_listen' with prob 0.98.
Action 'action_listen' ended with events '[]'
Rasa process starting
Restoring parameters from models/nlu/default/Banking_bot/intent_classifier_tensorflow_embedding.ckpt
Available web server routes: 
static                                             GET, OPTIONS, HEAD             /static/[filename]
custom_webhook_CmdlineInput.health                 GET, OPTIONS, HEAD             /webhooks/rest/
custom_webhook_CmdlineInput.receive                OPTIONS, POST                  /webhooks/rest/webhook
Rasa Core server is up and running on http://localhost:5005
Creating a new tracker for id 'default'.
Received user message 'can i take any loan' with intent '{'name': 'ask_faq_loan', 'confidence': 0.9547288417816162}' and entities '[]'
Logged UserUtterance - tracker now has 2 events
Current slot values: 

Current tracker state [None, None, None, {}, {'intent_ask_faq_loan': 1.0, 'prev_action_listen': 1.0}]
There is no memorised next action
Feature 'intent_ask_faq_loan' (value: '1.0') could not be found in feature map. Make sure you added all intents and entities to the domain
Predicted next action using policy_1_KerasPolicy
Predicted next action 'action_faqs' with prob 0.72.
Encountered an exception while running action 'action_faqs'. Bot will continue, but the actions events are lost. Make sure to fix the exception in your custom code.
The model predicted the custom action 'action_faqs' but you didn't configure an endpoint to run this custom action. Please take a look at the docs and set an endpoint configuration. https://rasa.com/docs/core/customactions/
Traceback (most recent call last):
  File "/home/omega/anaconda3/lib/python3.6/site-packages/rasa_core/processor.py", line 346, in _run_action
    events = action.run(dispatcher, tracker, self.domain)
  File "/home/omega/anaconda3/lib/python3.6/site-packages/rasa_core/actions/action.py", line 325, in run
    "".format(self.name(), DOCS_BASE_URL))
Exception: The model predicted the custom action 'action_faqs' but you didn't configure an endpoint to run this custom action. Please take a look at the docs and set an endpoint configuration. https://rasa.com/docs/core/customactions/
Action 'action_faqs' ended with events '[]'
Current tracker state [None, None, {}, {'intent_ask_faq_loan': 1.0, 'prev_action_listen': 1.0}, {'intent_ask_faq_loan': 1.0, 'prev_action_faqs': 1.0}]
There is no memorised next action
Feature 'intent_ask_faq_loan' (value: '1.0') could not be found in feature map. Make sure you added all intents and entities to the domain
Feature 'intent_ask_faq_loan' (value: '1.0') could not be found in feature map. Make sure you added all intents and entities to the domain
Predicted next action using policy_1_KerasPolicy
Predicted next action 'action_listen' with prob 0.98.
Action 'action_listen' ended with events '[]'
Rasa process starting
Restoring parameters from models/nlu/default/Banking_bot/intent_classifier_tensorflow_embedding.ckpt
Available web server routes: 
static                                             HEAD, OPTIONS, GET             /static/[filename]
custom_webhook_CmdlineInput.health                 HEAD, OPTIONS, GET             /webhooks/rest/
custom_webhook_CmdlineInput.receive                OPTIONS, POST                  /webhooks/rest/webhook
Rasa Core server is up and running on http://localhost:5005
Creating a new tracker for id 'default'.
Received user message 'can i take any loan' with intent '{'name': 'ask_faq_loan', 'confidence': 0.9547288417816162}' and entities '[]'
Logged UserUtterance - tracker now has 2 events
Current slot values: 

Current tracker state [None, None, None, {}, {'prev_action_listen': 1.0, 'intent_ask_faq_loan': 1.0}]
There is no memorised next action
Feature 'intent_ask_faq_loan' (value: '1.0') could not be found in feature map. Make sure you added all intents and entities to the domain
Predicted next action using policy_1_KerasPolicy
Predicted next action 'action_faqs' with prob 0.54.
Encountered an exception while running action 'action_faqs'. Bot will continue, but the actions events are lost. Make sure to fix the exception in your custom code.
The model predicted the custom action 'action_faqs' but you didn't configure an endpoint to run this custom action. Please take a look at the docs and set an endpoint configuration. https://rasa.com/docs/core/customactions/
Traceback (most recent call last):
  File "/home/omega/anaconda3/lib/python3.6/site-packages/rasa_core/processor.py", line 346, in _run_action
    events = action.run(dispatcher, tracker, self.domain)
  File "/home/omega/anaconda3/lib/python3.6/site-packages/rasa_core/actions/action.py", line 325, in run
    "".format(self.name(), DOCS_BASE_URL))
Exception: The model predicted the custom action 'action_faqs' but you didn't configure an endpoint to run this custom action. Please take a look at the docs and set an endpoint configuration. https://rasa.com/docs/core/customactions/
Action 'action_faqs' ended with events '[]'
Current tracker state [None, None, {}, {'prev_action_listen': 1.0, 'intent_ask_faq_loan': 1.0}, {'intent_ask_faq_loan': 1.0, 'prev_action_faqs': 1.0}]
There is no memorised next action
Feature 'intent_ask_faq_loan' (value: '1.0') could not be found in feature map. Make sure you added all intents and entities to the domain
Feature 'intent_ask_faq_loan' (value: '1.0') could not be found in feature map. Make sure you added all intents and entities to the domain
Predicted next action using policy_1_KerasPolicy
Predicted next action 'action_listen' with prob 0.95.
Action 'action_listen' ended with events '[]'
Rasa process starting
Restoring parameters from models/nlu/default/Banking_bot/intent_classifier_tensorflow_embedding.ckpt
Available web server routes: 
static                                             HEAD, OPTIONS, GET             /static/[filename]
custom_webhook_CmdlineInput.health                 HEAD, OPTIONS, GET             /webhooks/rest/
custom_webhook_CmdlineInput.receive                OPTIONS, POST                  /webhooks/rest/webhook
Rasa Core server is up and running on http://localhost:5005
Creating a new tracker for id 'default'.
Received user message 'car loan?' with intent '{'name': 'ask_faq_car_loan', 'confidence': 0.9319383502006531}' and entities '[]'
Logged UserUtterance - tracker now has 2 events
Current slot values: 

Current tracker state [None, None, None, {}, {'prev_action_listen': 1.0, 'intent_ask_faq_car_loan': 1.0}]
There is no memorised next action
Feature 'intent_ask_faq_car_loan' (value: '1.0') could not be found in feature map. Make sure you added all intents and entities to the domain
Predicted next action using policy_1_KerasPolicy
Predicted next action 'action_faqs' with prob 0.54.
Encountered an exception while running action 'action_faqs'. Bot will continue, but the actions events are lost. Make sure to fix the exception in your custom code.
The model predicted the custom action 'action_faqs' but you didn't configure an endpoint to run this custom action. Please take a look at the docs and set an endpoint configuration. https://rasa.com/docs/core/customactions/
Traceback (most recent call last):
  File "/home/omega/anaconda3/lib/python3.6/site-packages/rasa_core/processor.py", line 346, in _run_action
    events = action.run(dispatcher, tracker, self.domain)
  File "/home/omega/anaconda3/lib/python3.6/site-packages/rasa_core/actions/action.py", line 325, in run
    "".format(self.name(), DOCS_BASE_URL))
Exception: The model predicted the custom action 'action_faqs' but you didn't configure an endpoint to run this custom action. Please take a look at the docs and set an endpoint configuration. https://rasa.com/docs/core/customactions/
Action 'action_faqs' ended with events '[]'
Current tracker state [None, None, {}, {'prev_action_listen': 1.0, 'intent_ask_faq_car_loan': 1.0}, {'prev_action_faqs': 1.0, 'intent_ask_faq_car_loan': 1.0}]
There is no memorised next action
Feature 'intent_ask_faq_car_loan' (value: '1.0') could not be found in feature map. Make sure you added all intents and entities to the domain
Feature 'intent_ask_faq_car_loan' (value: '1.0') could not be found in feature map. Make sure you added all intents and entities to the domain
Predicted next action using policy_1_KerasPolicy
Predicted next action 'action_listen' with prob 0.95.
Action 'action_listen' ended with events '[]'
Rasa process starting
Restoring parameters from models/nlu/default/Banking_bot/intent_classifier_tensorflow_embedding.ckpt
Rasa process starting
Restoring parameters from models/nlu/default/Banking_bot/intent_classifier_tensorflow_embedding.ckpt
Available web server routes: 
static                                             GET, HEAD, OPTIONS             /static/[filename]
custom_webhook_CmdlineInput.health                 GET, HEAD, OPTIONS             /webhooks/rest/
custom_webhook_CmdlineInput.receive                POST, OPTIONS                  /webhooks/rest/webhook
Rasa Core server is up and running on http://localhost:5005
Creating a new tracker for id 'default'.
Received user message 'home loan?' with intent '{'name': 'ask_faq_home_loan', 'confidence': 0.9534329175949097}' and entities '[]'
Logged UserUtterance - tracker now has 2 events
Current slot values: 

Current tracker state [None, None, None, {}, {'intent_ask_faq_home_loan': 1.0, 'prev_action_listen': 1.0}]
There is no memorised next action
Feature 'intent_ask_faq_home_loan' (value: '1.0') could not be found in feature map. Make sure you added all intents and entities to the domain
Predicted next action using policy_1_KerasPolicy
Predicted next action 'action_faqs' with prob 0.73.
Encountered an exception while running action 'action_faqs'. Bot will continue, but the actions events are lost. Make sure to fix the exception in your custom code.
The model predicted the custom action 'action_faqs' but you didn't configure an endpoint to run this custom action. Please take a look at the docs and set an endpoint configuration. https://rasa.com/docs/core/customactions/
Traceback (most recent call last):
  File "/home/omega/anaconda3/lib/python3.6/site-packages/rasa_core/processor.py", line 346, in _run_action
    events = action.run(dispatcher, tracker, self.domain)
  File "/home/omega/anaconda3/lib/python3.6/site-packages/rasa_core/actions/action.py", line 325, in run
    "".format(self.name(), DOCS_BASE_URL))
Exception: The model predicted the custom action 'action_faqs' but you didn't configure an endpoint to run this custom action. Please take a look at the docs and set an endpoint configuration. https://rasa.com/docs/core/customactions/
Action 'action_faqs' ended with events '[]'
Current tracker state [None, None, {}, {'intent_ask_faq_home_loan': 1.0, 'prev_action_listen': 1.0}, {'intent_ask_faq_home_loan': 1.0, 'prev_action_faqs': 1.0}]
There is no memorised next action
Feature 'intent_ask_faq_home_loan' (value: '1.0') could not be found in feature map. Make sure you added all intents and entities to the domain
Feature 'intent_ask_faq_home_loan' (value: '1.0') could not be found in feature map. Make sure you added all intents and entities to the domain
Predicted next action using policy_1_KerasPolicy
Predicted next action 'action_listen' with prob 0.97.
Action 'action_listen' ended with events '[]'
Rasa process starting
Restoring parameters from models/nlu/default/Banking_bot/intent_classifier_tensorflow_embedding.ckpt
Available web server routes: 
static                                             HEAD, OPTIONS, GET             /static/[filename]
custom_webhook_CmdlineInput.health                 HEAD, OPTIONS, GET             /webhooks/rest/
custom_webhook_CmdlineInput.receive                OPTIONS, POST                  /webhooks/rest/webhook
Rasa Core server is up and running on http://localhost:5005
Creating a new tracker for id 'default'.
Received user message 'hi' with intent '{'name': 'greet', 'confidence': 0.9676894545555115}' and entities '[]'
Logged UserUtterance - tracker now has 2 events
Current slot values: 

Current tracker state [None, None, None, {}, {'intent_greet': 1.0, 'prev_action_listen': 1.0}]
There is a memorised next action '7'
Predicted next action using policy_0_MemoizationPolicy
Predicted next action 'utter_greet' with prob 1.00.
Action 'utter_greet' ended with events '[]'
Bot utterance 'BotUttered(text: Hello! How can i help?, data: {
  "elements": null,
  "buttons": null,
  "attachment": null
})'
Current tracker state [None, None, {}, {'intent_greet': 1.0, 'prev_action_listen': 1.0}, {'intent_greet': 1.0, 'prev_utter_greet': 1.0}]
There is a memorised next action '0'
Predicted next action using policy_0_MemoizationPolicy
Predicted next action 'action_listen' with prob 1.00.
Action 'action_listen' ended with events '[]'
Recreating tracker for id 'default'
Received user message 'car loan' with intent '{'name': 'ask_faq_car_loan', 'confidence': 0.9319383502006531}' and entities '[]'
Logged UserUtterance - tracker now has 6 events
Current slot values: 

Current tracker state [None, {}, {'intent_greet': 1.0, 'prev_action_listen': 1.0}, {'intent_greet': 1.0, 'prev_utter_greet': 1.0}, {'prev_action_listen': 1.0, 'intent_ask_faq_car_loan': 1.0}]
There is no memorised next action
Feature 'intent_ask_faq_car_loan' (value: '1.0') could not be found in feature map. Make sure you added all intents and entities to the domain
Predicted next action using policy_1_KerasPolicy
Predicted next action 'action_faqs' with prob 0.91.
Calling action endpoint to run action 'action_faqs'.
Failed to run custom action 'action_faqs'. Couldn't connect to the server at 'http://localhost:5055/webhook'. Is the server running? Error: HTTPConnectionPool(host='localhost', port=5055): Max retries exceeded with url: /webhook (Caused by NewConnectionError('<urllib3.connection.HTTPConnection object at 0x7f0d4c218780>: Failed to establish a new connection: [Errno 111] Connection refused',))
Encountered an exception while running action 'action_faqs'. Bot will continue, but the actions events are lost. Make sure to fix the exception in your custom code.
Failed to execute custom action.
Traceback (most recent call last):
  File "/home/omega/anaconda3/lib/python3.6/site-packages/urllib3/connection.py", line 171, in _new_conn
    (self._dns_host, self.port), self.timeout, **extra_kw)
  File "/home/omega/anaconda3/lib/python3.6/site-packages/urllib3/util/connection.py", line 79, in create_connection
    raise err
  File "/home/omega/anaconda3/lib/python3.6/site-packages/urllib3/util/connection.py", line 69, in create_connection
    sock.connect(sa)
ConnectionRefusedError: [Errno 111] Connection refused

During handling of the above exception, another exception occurred:

Traceback (most recent call last):
  File "/home/omega/anaconda3/lib/python3.6/site-packages/urllib3/connectionpool.py", line 600, in urlopen
    chunked=chunked)
  File "/home/omega/anaconda3/lib/python3.6/site-packages/urllib3/connectionpool.py", line 354, in _make_request
    conn.request(method, url, **httplib_request_kw)
  File "/home/omega/anaconda3/lib/python3.6/http/client.py", line 1239, in request
    self._send_request(method, url, body, headers, encode_chunked)
  File "/home/omega/anaconda3/lib/python3.6/http/client.py", line 1285, in _send_request
    self.endheaders(body, encode_chunked=encode_chunked)
  File "/home/omega/anaconda3/lib/python3.6/http/client.py", line 1234, in endheaders
    self._send_output(message_body, encode_chunked=encode_chunked)
  File "/home/omega/anaconda3/lib/python3.6/http/client.py", line 1026, in _send_output
    self.send(msg)
  File "/home/omega/anaconda3/lib/python3.6/http/client.py", line 964, in send
    self.connect()
  File "/home/omega/anaconda3/lib/python3.6/site-packages/urllib3/connection.py", line 196, in connect
    conn = self._new_conn()
  File "/home/omega/anaconda3/lib/python3.6/site-packages/urllib3/connection.py", line 180, in _new_conn
    self, "Failed to establish a new connection: %s" % e)
urllib3.exceptions.NewConnectionError: <urllib3.connection.HTTPConnection object at 0x7f0d4c218780>: Failed to establish a new connection: [Errno 111] Connection refused

During handling of the above exception, another exception occurred:

Traceback (most recent call last):
  File "/home/omega/anaconda3/lib/python3.6/site-packages/requests/adapters.py", line 449, in send
    timeout=timeout
  File "/home/omega/anaconda3/lib/python3.6/site-packages/urllib3/connectionpool.py", line 638, in urlopen
    _stacktrace=sys.exc_info()[2])
  File "/home/omega/anaconda3/lib/python3.6/site-packages/urllib3/util/retry.py", line 398, in increment
    raise MaxRetryError(_pool, url, error or ResponseError(cause))
urllib3.exceptions.MaxRetryError: HTTPConnectionPool(host='localhost', port=5055): Max retries exceeded with url: /webhook (Caused by NewConnectionError('<urllib3.connection.HTTPConnection object at 0x7f0d4c218780>: Failed to establish a new connection: [Errno 111] Connection refused',))

During handling of the above exception, another exception occurred:

Traceback (most recent call last):
  File "/home/omega/anaconda3/lib/python3.6/site-packages/rasa_core/actions/action.py", line 331, in run
    json=json, method="post", timeout=DEFAULT_REQUEST_TIMEOUT)
  File "/home/omega/anaconda3/lib/python3.6/site-packages/rasa_core/utils.py", line 667, in request
    **kwargs)
  File "/home/omega/anaconda3/lib/python3.6/site-packages/requests/api.py", line 60, in request
    return session.request(method=method, url=url, **kwargs)
  File "/home/omega/anaconda3/lib/python3.6/site-packages/requests/sessions.py", line 533, in request
    resp = self.send(prep, **send_kwargs)
  File "/home/omega/anaconda3/lib/python3.6/site-packages/requests/sessions.py", line 646, in send
    r = adapter.send(request, **kwargs)
  File "/home/omega/anaconda3/lib/python3.6/site-packages/requests/adapters.py", line 516, in send
    raise ConnectionError(e, request=request)
requests.exceptions.ConnectionError: HTTPConnectionPool(host='localhost', port=5055): Max retries exceeded with url: /webhook (Caused by NewConnectionError('<urllib3.connection.HTTPConnection object at 0x7f0d4c218780>: Failed to establish a new connection: [Errno 111] Connection refused',))

During handling of the above exception, another exception occurred:

Traceback (most recent call last):
  File "/home/omega/anaconda3/lib/python3.6/site-packages/rasa_core/processor.py", line 346, in _run_action
    events = action.run(dispatcher, tracker, self.domain)
  File "/home/omega/anaconda3/lib/python3.6/site-packages/rasa_core/actions/action.py", line 352, in run
    raise Exception("Failed to execute custom action.")
Exception: Failed to execute custom action.
Action 'action_faqs' ended with events '[]'
Current tracker state [{}, {'intent_greet': 1.0, 'prev_action_listen': 1.0}, {'intent_greet': 1.0, 'prev_utter_greet': 1.0}, {'prev_action_listen': 1.0, 'intent_ask_faq_car_loan': 1.0}, {'prev_action_faqs': 1.0, 'intent_ask_faq_car_loan': 1.0}]
There is no memorised next action
Feature 'intent_ask_faq_car_loan' (value: '1.0') could not be found in feature map. Make sure you added all intents and entities to the domain
Feature 'intent_ask_faq_car_loan' (value: '1.0') could not be found in feature map. Make sure you added all intents and entities to the domain
Predicted next action using policy_1_KerasPolicy
Predicted next action 'action_listen' with prob 0.99.
Action 'action_listen' ended with events '[]'
Rasa process starting
Restoring parameters from models/nlu/default/Banking_bot/intent_classifier_tensorflow_embedding.ckpt
Available web server routes: 
static                                             OPTIONS, HEAD, GET             /static/[filename]
custom_webhook_CmdlineInput.health                 OPTIONS, HEAD, GET             /webhooks/rest/
custom_webhook_CmdlineInput.receive                OPTIONS, POST                  /webhooks/rest/webhook
Rasa Core server is up and running on http://localhost:5005
Creating a new tracker for id 'default'.
Received user message 'car loan?' with intent '{'name': 'ask_faq_car_loan', 'confidence': 0.9319383502006531}' and entities '[]'
Logged UserUtterance - tracker now has 2 events
Current slot values: 

Current tracker state [None, None, None, {}, {'prev_action_listen': 1.0, 'intent_ask_faq_car_loan': 1.0}]
There is no memorised next action
Feature 'intent_ask_faq_car_loan' (value: '1.0') could not be found in feature map. Make sure you added all intents and entities to the domain
Predicted next action using policy_1_KerasPolicy
Predicted next action 'action_faqs' with prob 0.73.
Calling action endpoint to run action 'action_faqs'.
Failed to run custom action 'action_faqs'. Couldn't connect to the server at 'http://localhost:5055/webhook'. Is the server running? Error: HTTPConnectionPool(host='localhost', port=5055): Max retries exceeded with url: /webhook (Caused by NewConnectionError('<urllib3.connection.HTTPConnection object at 0x7f48b7fa9ba8>: Failed to establish a new connection: [Errno 111] Connection refused',))
Encountered an exception while running action 'action_faqs'. Bot will continue, but the actions events are lost. Make sure to fix the exception in your custom code.
Failed to execute custom action.
Traceback (most recent call last):
  File "/home/omega/anaconda3/lib/python3.6/site-packages/urllib3/connection.py", line 171, in _new_conn
    (self._dns_host, self.port), self.timeout, **extra_kw)
  File "/home/omega/anaconda3/lib/python3.6/site-packages/urllib3/util/connection.py", line 79, in create_connection
    raise err
  File "/home/omega/anaconda3/lib/python3.6/site-packages/urllib3/util/connection.py", line 69, in create_connection
    sock.connect(sa)
ConnectionRefusedError: [Errno 111] Connection refused

During handling of the above exception, another exception occurred:

Traceback (most recent call last):
  File "/home/omega/anaconda3/lib/python3.6/site-packages/urllib3/connectionpool.py", line 600, in urlopen
    chunked=chunked)
  File "/home/omega/anaconda3/lib/python3.6/site-packages/urllib3/connectionpool.py", line 354, in _make_request
    conn.request(method, url, **httplib_request_kw)
  File "/home/omega/anaconda3/lib/python3.6/http/client.py", line 1239, in request
    self._send_request(method, url, body, headers, encode_chunked)
  File "/home/omega/anaconda3/lib/python3.6/http/client.py", line 1285, in _send_request
    self.endheaders(body, encode_chunked=encode_chunked)
  File "/home/omega/anaconda3/lib/python3.6/http/client.py", line 1234, in endheaders
    self._send_output(message_body, encode_chunked=encode_chunked)
  File "/home/omega/anaconda3/lib/python3.6/http/client.py", line 1026, in _send_output
    self.send(msg)
  File "/home/omega/anaconda3/lib/python3.6/http/client.py", line 964, in send
    self.connect()
  File "/home/omega/anaconda3/lib/python3.6/site-packages/urllib3/connection.py", line 196, in connect
    conn = self._new_conn()
  File "/home/omega/anaconda3/lib/python3.6/site-packages/urllib3/connection.py", line 180, in _new_conn
    self, "Failed to establish a new connection: %s" % e)
urllib3.exceptions.NewConnectionError: <urllib3.connection.HTTPConnection object at 0x7f48b7fa9ba8>: Failed to establish a new connection: [Errno 111] Connection refused

During handling of the above exception, another exception occurred:

Traceback (most recent call last):
  File "/home/omega/anaconda3/lib/python3.6/site-packages/requests/adapters.py", line 449, in send
    timeout=timeout
  File "/home/omega/anaconda3/lib/python3.6/site-packages/urllib3/connectionpool.py", line 638, in urlopen
    _stacktrace=sys.exc_info()[2])
  File "/home/omega/anaconda3/lib/python3.6/site-packages/urllib3/util/retry.py", line 398, in increment
    raise MaxRetryError(_pool, url, error or ResponseError(cause))
urllib3.exceptions.MaxRetryError: HTTPConnectionPool(host='localhost', port=5055): Max retries exceeded with url: /webhook (Caused by NewConnectionError('<urllib3.connection.HTTPConnection object at 0x7f48b7fa9ba8>: Failed to establish a new connection: [Errno 111] Connection refused',))

During handling of the above exception, another exception occurred:

Traceback (most recent call last):
  File "/home/omega/anaconda3/lib/python3.6/site-packages/rasa_core/actions/action.py", line 331, in run
    json=json, method="post", timeout=DEFAULT_REQUEST_TIMEOUT)
  File "/home/omega/anaconda3/lib/python3.6/site-packages/rasa_core/utils.py", line 667, in request
    **kwargs)
  File "/home/omega/anaconda3/lib/python3.6/site-packages/requests/api.py", line 60, in request
    return session.request(method=method, url=url, **kwargs)
  File "/home/omega/anaconda3/lib/python3.6/site-packages/requests/sessions.py", line 533, in request
    resp = self.send(prep, **send_kwargs)
  File "/home/omega/anaconda3/lib/python3.6/site-packages/requests/sessions.py", line 646, in send
    r = adapter.send(request, **kwargs)
  File "/home/omega/anaconda3/lib/python3.6/site-packages/requests/adapters.py", line 516, in send
    raise ConnectionError(e, request=request)
requests.exceptions.ConnectionError: HTTPConnectionPool(host='localhost', port=5055): Max retries exceeded with url: /webhook (Caused by NewConnectionError('<urllib3.connection.HTTPConnection object at 0x7f48b7fa9ba8>: Failed to establish a new connection: [Errno 111] Connection refused',))

During handling of the above exception, another exception occurred:

Traceback (most recent call last):
  File "/home/omega/anaconda3/lib/python3.6/site-packages/rasa_core/processor.py", line 346, in _run_action
    events = action.run(dispatcher, tracker, self.domain)
  File "/home/omega/anaconda3/lib/python3.6/site-packages/rasa_core/actions/action.py", line 352, in run
    raise Exception("Failed to execute custom action.")
Exception: Failed to execute custom action.
Action 'action_faqs' ended with events '[]'
Current tracker state [None, None, {}, {'prev_action_listen': 1.0, 'intent_ask_faq_car_loan': 1.0}, {'prev_action_faqs': 1.0, 'intent_ask_faq_car_loan': 1.0}]
There is no memorised next action
Feature 'intent_ask_faq_car_loan' (value: '1.0') could not be found in feature map. Make sure you added all intents and entities to the domain
Feature 'intent_ask_faq_car_loan' (value: '1.0') could not be found in feature map. Make sure you added all intents and entities to the domain
Predicted next action using policy_1_KerasPolicy
Predicted next action 'action_listen' with prob 0.97.
Action 'action_listen' ended with events '[]'
Recreating tracker for id 'default'
Received user message 'hi there' with intent '{'name': 'greet', 'confidence': 0.979777455329895}' and entities '[]'
Logged UserUtterance - tracker now has 5 events
Current slot values: 

Current tracker state [None, {}, {'prev_action_listen': 1.0, 'intent_ask_faq_car_loan': 1.0}, {'prev_action_faqs': 1.0, 'intent_ask_faq_car_loan': 1.0}, {'prev_action_listen': 1.0, 'intent_greet': 1.0}]
There is no memorised next action
Feature 'intent_ask_faq_car_loan' (value: '1.0') could not be found in feature map. Make sure you added all intents and entities to the domain
Feature 'intent_ask_faq_car_loan' (value: '1.0') could not be found in feature map. Make sure you added all intents and entities to the domain
Predicted next action using policy_1_KerasPolicy
Predicted next action 'utter_goodbye' with prob 0.34.
Action 'utter_goodbye' ended with events '[]'
Bot utterance 'BotUttered(text: Bye, was nice talking to you!, data: {
  "elements": null,
  "buttons": null,
  "attachment": null
})'
Current tracker state [{}, {'prev_action_listen': 1.0, 'intent_ask_faq_car_loan': 1.0}, {'prev_action_faqs': 1.0, 'intent_ask_faq_car_loan': 1.0}, {'prev_action_listen': 1.0, 'intent_greet': 1.0}, {'prev_utter_goodbye': 1.0, 'intent_greet': 1.0}]
There is no memorised next action
Feature 'intent_ask_faq_car_loan' (value: '1.0') could not be found in feature map. Make sure you added all intents and entities to the domain
Predicted next action using policy_1_KerasPolicy
Predicted next action 'action_listen' with prob 0.98.
Action 'action_listen' ended with events '[]'
Recreating tracker for id 'default'
Received user message 'bye' with intent '{'name': 'goodbye', 'confidence': 0.9657748937606812}' and entities '[]'
Logged UserUtterance - tracker now has 9 events
Current slot values: 

Current tracker state [{'prev_action_listen': 1.0, 'intent_ask_faq_car_loan': 1.0}, {'prev_action_faqs': 1.0, 'intent_ask_faq_car_loan': 1.0}, {'prev_action_listen': 1.0, 'intent_greet': 1.0}, {'prev_utter_goodbye': 1.0, 'intent_greet': 1.0}, {'prev_action_listen': 1.0, 'intent_goodbye': 1.0}]
There is no memorised next action
Predicted next action using policy_1_KerasPolicy
Predicted next action 'action_faqs' with prob 0.51.
Calling action endpoint to run action 'action_faqs'.
Failed to run custom action 'action_faqs'. Couldn't connect to the server at 'http://localhost:5055/webhook'. Is the server running? Error: HTTPConnectionPool(host='localhost', port=5055): Max retries exceeded with url: /webhook (Caused by NewConnectionError('<urllib3.connection.HTTPConnection object at 0x7f48b4501978>: Failed to establish a new connection: [Errno 111] Connection refused',))
Encountered an exception while running action 'action_faqs'. Bot will continue, but the actions events are lost. Make sure to fix the exception in your custom code.
Failed to execute custom action.
Traceback (most recent call last):
  File "/home/omega/anaconda3/lib/python3.6/site-packages/urllib3/connection.py", line 171, in _new_conn
    (self._dns_host, self.port), self.timeout, **extra_kw)
  File "/home/omega/anaconda3/lib/python3.6/site-packages/urllib3/util/connection.py", line 79, in create_connection
    raise err
  File "/home/omega/anaconda3/lib/python3.6/site-packages/urllib3/util/connection.py", line 69, in create_connection
    sock.connect(sa)
ConnectionRefusedError: [Errno 111] Connection refused

During handling of the above exception, another exception occurred:

Traceback (most recent call last):
  File "/home/omega/anaconda3/lib/python3.6/site-packages/urllib3/connectionpool.py", line 600, in urlopen
    chunked=chunked)
  File "/home/omega/anaconda3/lib/python3.6/site-packages/urllib3/connectionpool.py", line 354, in _make_request
    conn.request(method, url, **httplib_request_kw)
  File "/home/omega/anaconda3/lib/python3.6/http/client.py", line 1239, in request
    self._send_request(method, url, body, headers, encode_chunked)
  File "/home/omega/anaconda3/lib/python3.6/http/client.py", line 1285, in _send_request
    self.endheaders(body, encode_chunked=encode_chunked)
  File "/home/omega/anaconda3/lib/python3.6/http/client.py", line 1234, in endheaders
    self._send_output(message_body, encode_chunked=encode_chunked)
  File "/home/omega/anaconda3/lib/python3.6/http/client.py", line 1026, in _send_output
    self.send(msg)
  File "/home/omega/anaconda3/lib/python3.6/http/client.py", line 964, in send
    self.connect()
  File "/home/omega/anaconda3/lib/python3.6/site-packages/urllib3/connection.py", line 196, in connect
    conn = self._new_conn()
  File "/home/omega/anaconda3/lib/python3.6/site-packages/urllib3/connection.py", line 180, in _new_conn
    self, "Failed to establish a new connection: %s" % e)
urllib3.exceptions.NewConnectionError: <urllib3.connection.HTTPConnection object at 0x7f48b4501978>: Failed to establish a new connection: [Errno 111] Connection refused

During handling of the above exception, another exception occurred:

Traceback (most recent call last):
  File "/home/omega/anaconda3/lib/python3.6/site-packages/requests/adapters.py", line 449, in send
    timeout=timeout
  File "/home/omega/anaconda3/lib/python3.6/site-packages/urllib3/connectionpool.py", line 638, in urlopen
    _stacktrace=sys.exc_info()[2])
  File "/home/omega/anaconda3/lib/python3.6/site-packages/urllib3/util/retry.py", line 398, in increment
    raise MaxRetryError(_pool, url, error or ResponseError(cause))
urllib3.exceptions.MaxRetryError: HTTPConnectionPool(host='localhost', port=5055): Max retries exceeded with url: /webhook (Caused by NewConnectionError('<urllib3.connection.HTTPConnection object at 0x7f48b4501978>: Failed to establish a new connection: [Errno 111] Connection refused',))

During handling of the above exception, another exception occurred:

Traceback (most recent call last):
  File "/home/omega/anaconda3/lib/python3.6/site-packages/rasa_core/actions/action.py", line 331, in run
    json=json, method="post", timeout=DEFAULT_REQUEST_TIMEOUT)
  File "/home/omega/anaconda3/lib/python3.6/site-packages/rasa_core/utils.py", line 667, in request
    **kwargs)
  File "/home/omega/anaconda3/lib/python3.6/site-packages/requests/api.py", line 60, in request
    return session.request(method=method, url=url, **kwargs)
  File "/home/omega/anaconda3/lib/python3.6/site-packages/requests/sessions.py", line 533, in request
    resp = self.send(prep, **send_kwargs)
  File "/home/omega/anaconda3/lib/python3.6/site-packages/requests/sessions.py", line 646, in send
    r = adapter.send(request, **kwargs)
  File "/home/omega/anaconda3/lib/python3.6/site-packages/requests/adapters.py", line 516, in send
    raise ConnectionError(e, request=request)
requests.exceptions.ConnectionError: HTTPConnectionPool(host='localhost', port=5055): Max retries exceeded with url: /webhook (Caused by NewConnectionError('<urllib3.connection.HTTPConnection object at 0x7f48b4501978>: Failed to establish a new connection: [Errno 111] Connection refused',))

During handling of the above exception, another exception occurred:

Traceback (most recent call last):
  File "/home/omega/anaconda3/lib/python3.6/site-packages/rasa_core/processor.py", line 346, in _run_action
    events = action.run(dispatcher, tracker, self.domain)
  File "/home/omega/anaconda3/lib/python3.6/site-packages/rasa_core/actions/action.py", line 352, in run
    raise Exception("Failed to execute custom action.")
Exception: Failed to execute custom action.
Action 'action_faqs' ended with events '[]'
Current tracker state [{'prev_action_faqs': 1.0, 'intent_ask_faq_car_loan': 1.0}, {'prev_action_listen': 1.0, 'intent_greet': 1.0}, {'prev_utter_goodbye': 1.0, 'intent_greet': 1.0}, {'prev_action_listen': 1.0, 'intent_goodbye': 1.0}, {'intent_goodbye': 1.0, 'prev_action_faqs': 1.0}]
There is no memorised next action
Predicted next action using policy_1_KerasPolicy
Predicted next action 'action_listen' with prob 0.99.
Action 'action_listen' ended with events '[]'
Recreating tracker for id 'default'
Received user message 'bye' with intent '{'name': 'goodbye', 'confidence': 0.9657748937606812}' and entities '[]'
Logged UserUtterance - tracker now has 12 events
Current slot values: 

Current tracker state [{'prev_action_listen': 1.0, 'intent_greet': 1.0}, {'prev_utter_goodbye': 1.0, 'intent_greet': 1.0}, {'prev_action_listen': 1.0, 'intent_goodbye': 1.0}, {'intent_goodbye': 1.0, 'prev_action_faqs': 1.0}, {'prev_action_listen': 1.0, 'intent_goodbye': 1.0}]
There is no memorised next action
Predicted next action using policy_1_KerasPolicy
Predicted next action 'utter_goodbye' with prob 0.41.
Action 'utter_goodbye' ended with events '[]'
Bot utterance 'BotUttered(text: Bye, was nice talking to you!, data: {
  "elements": null,
  "buttons": null,
  "attachment": null
})'
Current tracker state [{'prev_utter_goodbye': 1.0, 'intent_greet': 1.0}, {'prev_action_listen': 1.0, 'intent_goodbye': 1.0}, {'intent_goodbye': 1.0, 'prev_action_faqs': 1.0}, {'prev_action_listen': 1.0, 'intent_goodbye': 1.0}, {'intent_goodbye': 1.0, 'prev_utter_goodbye': 1.0}]
There is no memorised next action
Predicted next action using policy_1_KerasPolicy
Predicted next action 'action_listen' with prob 0.98.
Action 'action_listen' ended with events '[]'
Recreating tracker for id 'default'
Received user message 'hi again' with intent '{'name': 'greet', 'confidence': 0.9682537317276001}' and entities '[]'
Logged UserUtterance - tracker now has 16 events
Current slot values: 

Current tracker state [{'prev_action_listen': 1.0, 'intent_goodbye': 1.0}, {'intent_goodbye': 1.0, 'prev_action_faqs': 1.0}, {'prev_action_listen': 1.0, 'intent_goodbye': 1.0}, {'intent_goodbye': 1.0, 'prev_utter_goodbye': 1.0}, {'prev_action_listen': 1.0, 'intent_greet': 1.0}]
There is no memorised next action
Predicted next action using policy_1_KerasPolicy
Predicted next action 'action_faqs' with prob 0.47.
Calling action endpoint to run action 'action_faqs'.
Failed to run custom action 'action_faqs'. Couldn't connect to the server at 'http://localhost:5055/webhook'. Is the server running? Error: HTTPConnectionPool(host='localhost', port=5055): Max retries exceeded with url: /webhook (Caused by NewConnectionError('<urllib3.connection.HTTPConnection object at 0x7f48b8f3c710>: Failed to establish a new connection: [Errno 111] Connection refused',))
Encountered an exception while running action 'action_faqs'. Bot will continue, but the actions events are lost. Make sure to fix the exception in your custom code.
Failed to execute custom action.
Traceback (most recent call last):
  File "/home/omega/anaconda3/lib/python3.6/site-packages/urllib3/connection.py", line 171, in _new_conn
    (self._dns_host, self.port), self.timeout, **extra_kw)
  File "/home/omega/anaconda3/lib/python3.6/site-packages/urllib3/util/connection.py", line 79, in create_connection
    raise err
  File "/home/omega/anaconda3/lib/python3.6/site-packages/urllib3/util/connection.py", line 69, in create_connection
    sock.connect(sa)
ConnectionRefusedError: [Errno 111] Connection refused

During handling of the above exception, another exception occurred:

Traceback (most recent call last):
  File "/home/omega/anaconda3/lib/python3.6/site-packages/urllib3/connectionpool.py", line 600, in urlopen
    chunked=chunked)
  File "/home/omega/anaconda3/lib/python3.6/site-packages/urllib3/connectionpool.py", line 354, in _make_request
    conn.request(method, url, **httplib_request_kw)
  File "/home/omega/anaconda3/lib/python3.6/http/client.py", line 1239, in request
    self._send_request(method, url, body, headers, encode_chunked)
  File "/home/omega/anaconda3/lib/python3.6/http/client.py", line 1285, in _send_request
    self.endheaders(body, encode_chunked=encode_chunked)
  File "/home/omega/anaconda3/lib/python3.6/http/client.py", line 1234, in endheaders
    self._send_output(message_body, encode_chunked=encode_chunked)
  File "/home/omega/anaconda3/lib/python3.6/http/client.py", line 1026, in _send_output
    self.send(msg)
  File "/home/omega/anaconda3/lib/python3.6/http/client.py", line 964, in send
    self.connect()
  File "/home/omega/anaconda3/lib/python3.6/site-packages/urllib3/connection.py", line 196, in connect
    conn = self._new_conn()
  File "/home/omega/anaconda3/lib/python3.6/site-packages/urllib3/connection.py", line 180, in _new_conn
    self, "Failed to establish a new connection: %s" % e)
urllib3.exceptions.NewConnectionError: <urllib3.connection.HTTPConnection object at 0x7f48b8f3c710>: Failed to establish a new connection: [Errno 111] Connection refused

During handling of the above exception, another exception occurred:

Traceback (most recent call last):
  File "/home/omega/anaconda3/lib/python3.6/site-packages/requests/adapters.py", line 449, in send
    timeout=timeout
  File "/home/omega/anaconda3/lib/python3.6/site-packages/urllib3/connectionpool.py", line 638, in urlopen
    _stacktrace=sys.exc_info()[2])
  File "/home/omega/anaconda3/lib/python3.6/site-packages/urllib3/util/retry.py", line 398, in increment
    raise MaxRetryError(_pool, url, error or ResponseError(cause))
urllib3.exceptions.MaxRetryError: HTTPConnectionPool(host='localhost', port=5055): Max retries exceeded with url: /webhook (Caused by NewConnectionError('<urllib3.connection.HTTPConnection object at 0x7f48b8f3c710>: Failed to establish a new connection: [Errno 111] Connection refused',))

During handling of the above exception, another exception occurred:

Traceback (most recent call last):
  File "/home/omega/anaconda3/lib/python3.6/site-packages/rasa_core/actions/action.py", line 331, in run
    json=json, method="post", timeout=DEFAULT_REQUEST_TIMEOUT)
  File "/home/omega/anaconda3/lib/python3.6/site-packages/rasa_core/utils.py", line 667, in request
    **kwargs)
  File "/home/omega/anaconda3/lib/python3.6/site-packages/requests/api.py", line 60, in request
    return session.request(method=method, url=url, **kwargs)
  File "/home/omega/anaconda3/lib/python3.6/site-packages/requests/sessions.py", line 533, in request
    resp = self.send(prep, **send_kwargs)
  File "/home/omega/anaconda3/lib/python3.6/site-packages/requests/sessions.py", line 646, in send
    r = adapter.send(request, **kwargs)
  File "/home/omega/anaconda3/lib/python3.6/site-packages/requests/adapters.py", line 516, in send
    raise ConnectionError(e, request=request)
requests.exceptions.ConnectionError: HTTPConnectionPool(host='localhost', port=5055): Max retries exceeded with url: /webhook (Caused by NewConnectionError('<urllib3.connection.HTTPConnection object at 0x7f48b8f3c710>: Failed to establish a new connection: [Errno 111] Connection refused',))

During handling of the above exception, another exception occurred:

Traceback (most recent call last):
  File "/home/omega/anaconda3/lib/python3.6/site-packages/rasa_core/processor.py", line 346, in _run_action
    events = action.run(dispatcher, tracker, self.domain)
  File "/home/omega/anaconda3/lib/python3.6/site-packages/rasa_core/actions/action.py", line 352, in run
    raise Exception("Failed to execute custom action.")
Exception: Failed to execute custom action.
Action 'action_faqs' ended with events '[]'
Current tracker state [{'intent_goodbye': 1.0, 'prev_action_faqs': 1.0}, {'prev_action_listen': 1.0, 'intent_goodbye': 1.0}, {'intent_goodbye': 1.0, 'prev_utter_goodbye': 1.0}, {'prev_action_listen': 1.0, 'intent_greet': 1.0}, {'prev_action_faqs': 1.0, 'intent_greet': 1.0}]
There is no memorised next action
Predicted next action using policy_1_KerasPolicy
Predicted next action 'action_listen' with prob 0.98.
Action 'action_listen' ended with events '[]'
Rasa process starting
Restoring parameters from models/nlu/default/Banking_bot/intent_classifier_tensorflow_embedding.ckpt
Available web server routes: 
static                                             HEAD, OPTIONS, GET             /static/[filename]
custom_webhook_CmdlineInput.health                 HEAD, OPTIONS, GET             /webhooks/rest/
custom_webhook_CmdlineInput.receive                OPTIONS, POST                  /webhooks/rest/webhook
Rasa Core server is up and running on http://localhost:5005
Creating a new tracker for id 'default'.
Received user message 'car loan?' with intent '{'name': 'ask_faq_car_loan', 'confidence': 0.9319383502006531}' and entities '[]'
Logged UserUtterance - tracker now has 2 events
Current slot values: 

Current tracker state [None, None, None, {}, {'prev_action_listen': 1.0, 'intent_ask_faq_car_loan': 1.0}]
There is no memorised next action
Feature 'intent_ask_faq_car_loan' (value: '1.0') could not be found in feature map. Make sure you added all intents and entities to the domain
Predicted next action using policy_1_KerasPolicy
Predicted next action 'action_faqs' with prob 0.73.
Encountered an exception while running action 'action_faqs'. Bot will continue, but the actions events are lost. Make sure to fix the exception in your custom code.
The model predicted the custom action 'action_faqs' but you didn't configure an endpoint to run this custom action. Please take a look at the docs and set an endpoint configuration. https://rasa.com/docs/core/customactions/
Traceback (most recent call last):
  File "/home/omega/anaconda3/lib/python3.6/site-packages/rasa_core/processor.py", line 346, in _run_action
    events = action.run(dispatcher, tracker, self.domain)
  File "/home/omega/anaconda3/lib/python3.6/site-packages/rasa_core/actions/action.py", line 325, in run
    "".format(self.name(), DOCS_BASE_URL))
Exception: The model predicted the custom action 'action_faqs' but you didn't configure an endpoint to run this custom action. Please take a look at the docs and set an endpoint configuration. https://rasa.com/docs/core/customactions/
Action 'action_faqs' ended with events '[]'
Current tracker state [None, None, {}, {'prev_action_listen': 1.0, 'intent_ask_faq_car_loan': 1.0}, {'prev_action_faqs': 1.0, 'intent_ask_faq_car_loan': 1.0}]
There is no memorised next action
Feature 'intent_ask_faq_car_loan' (value: '1.0') could not be found in feature map. Make sure you added all intents and entities to the domain
Feature 'intent_ask_faq_car_loan' (value: '1.0') could not be found in feature map. Make sure you added all intents and entities to the domain
Predicted next action using policy_1_KerasPolicy
Predicted next action 'action_listen' with prob 0.97.
Action 'action_listen' ended with events '[]'
Rasa process starting
Restoring parameters from models/nlu/default/Banking_bot/intent_classifier_tensorflow_embedding.ckpt
Available web server routes: 
static                                             HEAD, OPTIONS, GET             /static/[filename]
custom_webhook_CmdlineInput.health                 HEAD, OPTIONS, GET             /webhooks/rest/
custom_webhook_CmdlineInput.receive                POST, OPTIONS                  /webhooks/rest/webhook
Rasa Core server is up and running on http://localhost:5005
Creating a new tracker for id 'default'.
Received user message 'car loan?' with intent '{'name': 'ask_faq_car_loan', 'confidence': 0.9319383502006531}' and entities '[]'
Logged UserUtterance - tracker now has 2 events
Current slot values: 

Current tracker state [None, None, None, {}, {'intent_ask_faq_car_loan': 1.0, 'prev_action_listen': 1.0}]
There is no memorised next action
Feature 'intent_ask_faq_car_loan' (value: '1.0') could not be found in feature map. Make sure you added all intents and entities to the domain
Predicted next action using policy_1_KerasPolicy
Predicted next action 'action_faqs' with prob 0.73.
Calling action endpoint to run action 'action_faqs'.
Failed to run custom action 'action_faqs'. Couldn't connect to the server at 'http://localhost:5055/webhook'. Is the server running? Error: HTTPConnectionPool(host='localhost', port=5055): Max retries exceeded with url: /webhook (Caused by NewConnectionError('<urllib3.connection.HTTPConnection object at 0x7fbd228a9eb8>: Failed to establish a new connection: [Errno 111] Connection refused',))
Encountered an exception while running action 'action_faqs'. Bot will continue, but the actions events are lost. Make sure to fix the exception in your custom code.
Failed to execute custom action.
Traceback (most recent call last):
  File "/home/omega/anaconda3/lib/python3.6/site-packages/urllib3/connection.py", line 171, in _new_conn
    (self._dns_host, self.port), self.timeout, **extra_kw)
  File "/home/omega/anaconda3/lib/python3.6/site-packages/urllib3/util/connection.py", line 79, in create_connection
    raise err
  File "/home/omega/anaconda3/lib/python3.6/site-packages/urllib3/util/connection.py", line 69, in create_connection
    sock.connect(sa)
ConnectionRefusedError: [Errno 111] Connection refused

During handling of the above exception, another exception occurred:

Traceback (most recent call last):
  File "/home/omega/anaconda3/lib/python3.6/site-packages/urllib3/connectionpool.py", line 600, in urlopen
    chunked=chunked)
  File "/home/omega/anaconda3/lib/python3.6/site-packages/urllib3/connectionpool.py", line 354, in _make_request
    conn.request(method, url, **httplib_request_kw)
  File "/home/omega/anaconda3/lib/python3.6/http/client.py", line 1239, in request
    self._send_request(method, url, body, headers, encode_chunked)
  File "/home/omega/anaconda3/lib/python3.6/http/client.py", line 1285, in _send_request
    self.endheaders(body, encode_chunked=encode_chunked)
  File "/home/omega/anaconda3/lib/python3.6/http/client.py", line 1234, in endheaders
    self._send_output(message_body, encode_chunked=encode_chunked)
  File "/home/omega/anaconda3/lib/python3.6/http/client.py", line 1026, in _send_output
    self.send(msg)
  File "/home/omega/anaconda3/lib/python3.6/http/client.py", line 964, in send
    self.connect()
  File "/home/omega/anaconda3/lib/python3.6/site-packages/urllib3/connection.py", line 196, in connect
    conn = self._new_conn()
  File "/home/omega/anaconda3/lib/python3.6/site-packages/urllib3/connection.py", line 180, in _new_conn
    self, "Failed to establish a new connection: %s" % e)
urllib3.exceptions.NewConnectionError: <urllib3.connection.HTTPConnection object at 0x7fbd228a9eb8>: Failed to establish a new connection: [Errno 111] Connection refused

During handling of the above exception, another exception occurred:

Traceback (most recent call last):
  File "/home/omega/anaconda3/lib/python3.6/site-packages/requests/adapters.py", line 449, in send
    timeout=timeout
  File "/home/omega/anaconda3/lib/python3.6/site-packages/urllib3/connectionpool.py", line 638, in urlopen
    _stacktrace=sys.exc_info()[2])
  File "/home/omega/anaconda3/lib/python3.6/site-packages/urllib3/util/retry.py", line 398, in increment
    raise MaxRetryError(_pool, url, error or ResponseError(cause))
urllib3.exceptions.MaxRetryError: HTTPConnectionPool(host='localhost', port=5055): Max retries exceeded with url: /webhook (Caused by NewConnectionError('<urllib3.connection.HTTPConnection object at 0x7fbd228a9eb8>: Failed to establish a new connection: [Errno 111] Connection refused',))

During handling of the above exception, another exception occurred:

Traceback (most recent call last):
  File "/home/omega/anaconda3/lib/python3.6/site-packages/rasa_core/actions/action.py", line 331, in run
    json=json, method="post", timeout=DEFAULT_REQUEST_TIMEOUT)
  File "/home/omega/anaconda3/lib/python3.6/site-packages/rasa_core/utils.py", line 667, in request
    **kwargs)
  File "/home/omega/anaconda3/lib/python3.6/site-packages/requests/api.py", line 60, in request
    return session.request(method=method, url=url, **kwargs)
  File "/home/omega/anaconda3/lib/python3.6/site-packages/requests/sessions.py", line 533, in request
    resp = self.send(prep, **send_kwargs)
  File "/home/omega/anaconda3/lib/python3.6/site-packages/requests/sessions.py", line 646, in send
    r = adapter.send(request, **kwargs)
  File "/home/omega/anaconda3/lib/python3.6/site-packages/requests/adapters.py", line 516, in send
    raise ConnectionError(e, request=request)
requests.exceptions.ConnectionError: HTTPConnectionPool(host='localhost', port=5055): Max retries exceeded with url: /webhook (Caused by NewConnectionError('<urllib3.connection.HTTPConnection object at 0x7fbd228a9eb8>: Failed to establish a new connection: [Errno 111] Connection refused',))

During handling of the above exception, another exception occurred:

Traceback (most recent call last):
  File "/home/omega/anaconda3/lib/python3.6/site-packages/rasa_core/processor.py", line 346, in _run_action
    events = action.run(dispatcher, tracker, self.domain)
  File "/home/omega/anaconda3/lib/python3.6/site-packages/rasa_core/actions/action.py", line 352, in run
    raise Exception("Failed to execute custom action.")
Exception: Failed to execute custom action.
Action 'action_faqs' ended with events '[]'
Current tracker state [None, None, {}, {'intent_ask_faq_car_loan': 1.0, 'prev_action_listen': 1.0}, {'prev_action_faqs': 1.0, 'intent_ask_faq_car_loan': 1.0}]
There is no memorised next action
Feature 'intent_ask_faq_car_loan' (value: '1.0') could not be found in feature map. Make sure you added all intents and entities to the domain
Feature 'intent_ask_faq_car_loan' (value: '1.0') could not be found in feature map. Make sure you added all intents and entities to the domain
Predicted next action using policy_1_KerasPolicy
Predicted next action 'action_listen' with prob 0.97.
Action 'action_listen' ended with events '[]'
Rasa process starting
Restoring parameters from models/nlu/default/Banking_bot/intent_classifier_tensorflow_embedding.ckpt
Available web server routes: 
static                                             OPTIONS, HEAD, GET             /static/[filename]
custom_webhook_CmdlineInput.health                 OPTIONS, HEAD, GET             /webhooks/rest/
custom_webhook_CmdlineInput.receive                OPTIONS, POST                  /webhooks/rest/webhook
Rasa Core server is up and running on http://localhost:5005
Creating a new tracker for id 'default'.
Received user message 'car loan?' with intent '{'name': 'ask_faq_car_loan', 'confidence': 0.9319383502006531}' and entities '[]'
Logged UserUtterance - tracker now has 2 events
Current slot values: 

Current tracker state [None, None, None, {}, {'prev_action_listen': 1.0, 'intent_ask_faq_car_loan': 1.0}]
There is no memorised next action
Feature 'intent_ask_faq_car_loan' (value: '1.0') could not be found in feature map. Make sure you added all intents and entities to the domain
Predicted next action using policy_1_KerasPolicy
Predicted next action 'action_faqs' with prob 0.73.
Calling action endpoint to run action 'action_faqs'.
Failed to run custom action 'action_faqs'. Action server responded with a non 200 status code of 500. Make sure your action server properly runs actions and returns a 200 once the action is executed. Error: 500 Server Error: INTERNAL SERVER ERROR for url: http://localhost:5055/webhook
Encountered an exception while running action 'action_faqs'. Bot will continue, but the actions events are lost. Make sure to fix the exception in your custom code.
Failed to execute custom action.
Traceback (most recent call last):
  File "/home/omega/anaconda3/lib/python3.6/site-packages/rasa_core/actions/action.py", line 342, in run
    response.raise_for_status()
  File "/home/omega/anaconda3/lib/python3.6/site-packages/requests/models.py", line 940, in raise_for_status
    raise HTTPError(http_error_msg, response=self)
requests.exceptions.HTTPError: 500 Server Error: INTERNAL SERVER ERROR for url: http://localhost:5055/webhook

During handling of the above exception, another exception occurred:

Traceback (most recent call last):
  File "/home/omega/anaconda3/lib/python3.6/site-packages/rasa_core/processor.py", line 346, in _run_action
    events = action.run(dispatcher, tracker, self.domain)
  File "/home/omega/anaconda3/lib/python3.6/site-packages/rasa_core/actions/action.py", line 362, in run
    raise Exception("Failed to execute custom action.")
Exception: Failed to execute custom action.
Action 'action_faqs' ended with events '[]'
Current tracker state [None, None, {}, {'prev_action_listen': 1.0, 'intent_ask_faq_car_loan': 1.0}, {'intent_ask_faq_car_loan': 1.0, 'prev_action_faqs': 1.0}]
There is no memorised next action
Feature 'intent_ask_faq_car_loan' (value: '1.0') could not be found in feature map. Make sure you added all intents and entities to the domain
Feature 'intent_ask_faq_car_loan' (value: '1.0') could not be found in feature map. Make sure you added all intents and entities to the domain
Predicted next action using policy_1_KerasPolicy
Predicted next action 'action_listen' with prob 0.97.
Action 'action_listen' ended with events '[]'
Rasa process starting
Restoring parameters from models/nlu/default/Banking_bot/intent_classifier_tensorflow_embedding.ckpt
Available web server routes: 
static                                             GET, OPTIONS, HEAD             /static/[filename]
custom_webhook_CmdlineInput.health                 GET, OPTIONS, HEAD             /webhooks/rest/
custom_webhook_CmdlineInput.receive                OPTIONS, POST                  /webhooks/rest/webhook
Rasa Core server is up and running on http://localhost:5005
Creating a new tracker for id 'default'.
Received user message 'car loan?' with intent '{'name': 'ask_faq_car_loan', 'confidence': 0.9319383502006531}' and entities '[]'
Logged UserUtterance - tracker now has 2 events
Current slot values: 

Current tracker state [None, None, None, {}, {'intent_ask_faq_car_loan': 1.0, 'prev_action_listen': 1.0}]
There is no memorised next action
Feature 'intent_ask_faq_car_loan' (value: '1.0') could not be found in feature map. Make sure you added all intents and entities to the domain
Predicted next action using policy_1_KerasPolicy
Predicted next action 'action_faqs' with prob 0.73.
Calling action endpoint to run action 'action_faqs'.
Action 'action_faqs' ended with events '[]'
Bot utterance 'BotUttered(text: If you are a salaried or self-employed business person/professional having a regular, stable and verifiable income stream , you can apply for HBL CarLoan., data: {
  "elements": null,
  "buttons": null,
  "attachment": null
})'
Current tracker state [None, None, {}, {'intent_ask_faq_car_loan': 1.0, 'prev_action_listen': 1.0}, {'prev_action_faqs': 1.0, 'intent_ask_faq_car_loan': 1.0}]
There is no memorised next action
Feature 'intent_ask_faq_car_loan' (value: '1.0') could not be found in feature map. Make sure you added all intents and entities to the domain
Feature 'intent_ask_faq_car_loan' (value: '1.0') could not be found in feature map. Make sure you added all intents and entities to the domain
Predicted next action using policy_1_KerasPolicy
Predicted next action 'action_listen' with prob 0.97.
Action 'action_listen' ended with events '[]'
Recreating tracker for id 'default'
Received user message 'how can i get home loan?' with intent '{'name': 'ask_faq_home_loan', 'confidence': 0.8933833837509155}' and entities '[]'
Logged UserUtterance - tracker now has 6 events
Current slot values: 

Current tracker state [None, {}, {'intent_ask_faq_car_loan': 1.0, 'prev_action_listen': 1.0}, {'prev_action_faqs': 1.0, 'intent_ask_faq_car_loan': 1.0}, {'prev_action_listen': 1.0, 'intent_ask_faq_home_loan': 1.0}]
There is no memorised next action
Feature 'intent_ask_faq_car_loan' (value: '1.0') could not be found in feature map. Make sure you added all intents and entities to the domain
Feature 'intent_ask_faq_car_loan' (value: '1.0') could not be found in feature map. Make sure you added all intents and entities to the domain
Feature 'intent_ask_faq_home_loan' (value: '1.0') could not be found in feature map. Make sure you added all intents and entities to the domain
Predicted next action using policy_1_KerasPolicy
Predicted next action 'action_faqs' with prob 0.79.
Calling action endpoint to run action 'action_faqs'.
Action 'action_faqs' ended with events '[]'
Bot utterance 'BotUttered(text: Any salaried or self-employed business person / professional with a regular, stable and verifiable income stream can apply for HBL HomeLoan., data: {
  "elements": null,
  "buttons": null,
  "attachment": null
})'
Current tracker state [{}, {'intent_ask_faq_car_loan': 1.0, 'prev_action_listen': 1.0}, {'prev_action_faqs': 1.0, 'intent_ask_faq_car_loan': 1.0}, {'prev_action_listen': 1.0, 'intent_ask_faq_home_loan': 1.0}, {'prev_action_faqs': 1.0, 'intent_ask_faq_home_loan': 1.0}]
There is no memorised next action
Feature 'intent_ask_faq_car_loan' (value: '1.0') could not be found in feature map. Make sure you added all intents and entities to the domain
Feature 'intent_ask_faq_home_loan' (value: '1.0') could not be found in feature map. Make sure you added all intents and entities to the domain
Feature 'intent_ask_faq_home_loan' (value: '1.0') could not be found in feature map. Make sure you added all intents and entities to the domain
Predicted next action using policy_1_KerasPolicy
Predicted next action 'action_listen' with prob 0.98.
Action 'action_listen' ended with events '[]'
Recreating tracker for id 'default'
Received user message 'can i take any loan?' with intent '{'name': 'ask_faq_loan', 'confidence': 0.9547288417816162}' and entities '[]'
Logged UserUtterance - tracker now has 10 events
Current slot values: 

Current tracker state [{'intent_ask_faq_car_loan': 1.0, 'prev_action_listen': 1.0}, {'prev_action_faqs': 1.0, 'intent_ask_faq_car_loan': 1.0}, {'prev_action_listen': 1.0, 'intent_ask_faq_home_loan': 1.0}, {'prev_action_faqs': 1.0, 'intent_ask_faq_home_loan': 1.0}, {'intent_ask_faq_loan': 1.0, 'prev_action_listen': 1.0}]
There is no memorised next action
Feature 'intent_ask_faq_home_loan' (value: '1.0') could not be found in feature map. Make sure you added all intents and entities to the domain
Feature 'intent_ask_faq_home_loan' (value: '1.0') could not be found in feature map. Make sure you added all intents and entities to the domain
Feature 'intent_ask_faq_loan' (value: '1.0') could not be found in feature map. Make sure you added all intents and entities to the domain
Predicted next action using policy_1_KerasPolicy
Predicted next action 'action_faqs' with prob 0.79.
Calling action endpoint to run action 'action_faqs'.
Action 'action_faqs' ended with events '[]'
Bot utterance 'BotUttered(text: what kind of loan you are talking about? Home loan? Car loan ?, data: {
  "elements": null,
  "buttons": null,
  "attachment": null
})'
Current tracker state [{'prev_action_faqs': 1.0, 'intent_ask_faq_car_loan': 1.0}, {'prev_action_listen': 1.0, 'intent_ask_faq_home_loan': 1.0}, {'prev_action_faqs': 1.0, 'intent_ask_faq_home_loan': 1.0}, {'intent_ask_faq_loan': 1.0, 'prev_action_listen': 1.0}, {'prev_action_faqs': 1.0, 'intent_ask_faq_loan': 1.0}]
There is no memorised next action
Feature 'intent_ask_faq_home_loan' (value: '1.0') could not be found in feature map. Make sure you added all intents and entities to the domain
Feature 'intent_ask_faq_loan' (value: '1.0') could not be found in feature map. Make sure you added all intents and entities to the domain
Feature 'intent_ask_faq_loan' (value: '1.0') could not be found in feature map. Make sure you added all intents and entities to the domain
Predicted next action using policy_1_KerasPolicy
Predicted next action 'action_listen' with prob 0.98.
Action 'action_listen' ended with events '[]'
Recreating tracker for id 'default'
Received user message 'home loan?' with intent '{'name': 'ask_faq_home_loan', 'confidence': 0.9534329175949097}' and entities '[]'
Logged UserUtterance - tracker now has 14 events
Current slot values: 

Current tracker state [{'prev_action_listen': 1.0, 'intent_ask_faq_home_loan': 1.0}, {'prev_action_faqs': 1.0, 'intent_ask_faq_home_loan': 1.0}, {'intent_ask_faq_loan': 1.0, 'prev_action_listen': 1.0}, {'prev_action_faqs': 1.0, 'intent_ask_faq_loan': 1.0}, {'prev_action_listen': 1.0, 'intent_ask_faq_home_loan': 1.0}]
There is no memorised next action
Feature 'intent_ask_faq_loan' (value: '1.0') could not be found in feature map. Make sure you added all intents and entities to the domain
Feature 'intent_ask_faq_loan' (value: '1.0') could not be found in feature map. Make sure you added all intents and entities to the domain
Feature 'intent_ask_faq_home_loan' (value: '1.0') could not be found in feature map. Make sure you added all intents and entities to the domain
Predicted next action using policy_1_KerasPolicy
Predicted next action 'action_faqs' with prob 0.79.
Calling action endpoint to run action 'action_faqs'.
Action 'action_faqs' ended with events '[]'
Bot utterance 'BotUttered(text: Any salaried or self-employed business person / professional with a regular, stable and verifiable income stream can apply for HBL HomeLoan., data: {
  "elements": null,
  "buttons": null,
  "attachment": null
})'
Current tracker state [{'prev_action_faqs': 1.0, 'intent_ask_faq_home_loan': 1.0}, {'intent_ask_faq_loan': 1.0, 'prev_action_listen': 1.0}, {'prev_action_faqs': 1.0, 'intent_ask_faq_loan': 1.0}, {'prev_action_listen': 1.0, 'intent_ask_faq_home_loan': 1.0}, {'prev_action_faqs': 1.0, 'intent_ask_faq_home_loan': 1.0}]
There is no memorised next action
Feature 'intent_ask_faq_loan' (value: '1.0') could not be found in feature map. Make sure you added all intents and entities to the domain
Feature 'intent_ask_faq_home_loan' (value: '1.0') could not be found in feature map. Make sure you added all intents and entities to the domain
Feature 'intent_ask_faq_home_loan' (value: '1.0') could not be found in feature map. Make sure you added all intents and entities to the domain
Predicted next action using policy_1_KerasPolicy
Predicted next action 'action_listen' with prob 0.98.
Action 'action_listen' ended with events '[]'
Rasa process starting
Restoring parameters from models/nlu/default/Banking_bot/intent_classifier_tensorflow_embedding.ckpt
Restoring parameters from models/dialogue/policy_1_EmbeddingPolicy/tensorflow_embedding.ckpt
Available web server routes: 
static                                             HEAD, OPTIONS, GET             /static/[filename]
custom_webhook_CmdlineInput.health                 HEAD, OPTIONS, GET             /webhooks/rest/
custom_webhook_CmdlineInput.receive                OPTIONS, POST                  /webhooks/rest/webhook
Rasa Core server is up and running on http://localhost:5005
Creating a new tracker for id 'default'.
Received user message 'car loan' with intent '{'name': 'ask_faq_car_loan', 'confidence': 0.9618583917617798}' and entities '[]'
Logged UserUtterance - tracker now has 2 events
Current slot values: 

Current tracker state [None, None, None, {}, {'intent_ask_faq_car_loan': 1.0, 'prev_action_listen': 1.0}]
There is no memorised next action
Feature 'intent_ask_faq_car_loan' could not be found in feature map.
Predicted next action using policy_1_EmbeddingPolicy
Predicted next action 'action_listen' with prob 0.75.
Action 'action_listen' ended with events '[]'
Rasa process starting
Restoring parameters from models/nlu/default/Banking_bot/intent_classifier_tensorflow_embedding.ckpt
Restoring parameters from models/dialogue/policy_1_EmbeddingPolicy/tensorflow_embedding.ckpt
Available web server routes: 
static                                             HEAD, OPTIONS, GET             /static/[filename]
custom_webhook_CmdlineInput.health                 HEAD, OPTIONS, GET             /webhooks/rest/
custom_webhook_CmdlineInput.receive                POST, OPTIONS                  /webhooks/rest/webhook
Rasa Core server is up and running on http://localhost:5005
Creating a new tracker for id 'default'.
Received user message 'hi' with intent '{'name': 'greet', 'confidence': 0.9492543339729309}' and entities '[]'
Logged UserUtterance - tracker now has 2 events
Current slot values: 

Current tracker state [None, None, None, {}, {'intent_greet': 1.0, 'prev_action_listen': 1.0}]
There is a memorised next action '7'
Predicted next action using policy_0_MemoizationPolicy
Predicted next action 'utter_greet' with prob 1.00.
Action 'utter_greet' ended with events '[]'
Bot utterance 'BotUttered(text: Hello! How can i help?, data: {
  "elements": null,
  "buttons": null,
  "attachment": null
})'
Current tracker state [None, None, {}, {'intent_greet': 1.0, 'prev_action_listen': 1.0}, {'prev_utter_greet': 1.0, 'intent_greet': 1.0}]
There is a memorised next action '0'
Predicted next action using policy_0_MemoizationPolicy
Predicted next action 'action_listen' with prob 1.00.
Action 'action_listen' ended with events '[]'
Recreating tracker for id 'default'
Received user message 'hi' with intent '{'name': 'greet', 'confidence': 0.9492543339729309}' and entities '[]'
Logged UserUtterance - tracker now has 6 events
Current slot values: 

Current tracker state [None, {}, {'intent_greet': 1.0, 'prev_action_listen': 1.0}, {'prev_utter_greet': 1.0, 'intent_greet': 1.0}, {'intent_greet': 1.0, 'prev_action_listen': 1.0}]
There is no memorised next action
Predicted next action using policy_1_EmbeddingPolicy
Predicted next action 'utter_greet' with prob 1.00.
Action 'utter_greet' ended with events '[]'
Bot utterance 'BotUttered(text: Hi there beautiful :), data: {
  "elements": null,
  "buttons": null,
  "attachment": null
})'
Current tracker state [{}, {'intent_greet': 1.0, 'prev_action_listen': 1.0}, {'prev_utter_greet': 1.0, 'intent_greet': 1.0}, {'intent_greet': 1.0, 'prev_action_listen': 1.0}, {'prev_utter_greet': 1.0, 'intent_greet': 1.0}]
There is no memorised next action
Predicted next action using policy_1_EmbeddingPolicy
Predicted next action 'action_listen' with prob 0.72.
Action 'action_listen' ended with events '[]'
Recreating tracker for id 'default'
Received user message 'car loan' with intent '{'name': 'ask_faq_car_loan', 'confidence': 0.9618583917617798}' and entities '[]'
Logged UserUtterance - tracker now has 10 events
Current slot values: 

Current tracker state [{'intent_greet': 1.0, 'prev_action_listen': 1.0}, {'prev_utter_greet': 1.0, 'intent_greet': 1.0}, {'intent_greet': 1.0, 'prev_action_listen': 1.0}, {'prev_utter_greet': 1.0, 'intent_greet': 1.0}, {'intent_ask_faq_car_loan': 1.0, 'prev_action_listen': 1.0}]
There is no memorised next action
Feature 'intent_ask_faq_car_loan' could not be found in feature map.
Predicted next action using policy_1_EmbeddingPolicy
Predicted next action 'utter_greet' with prob 1.00.
Action 'utter_greet' ended with events '[]'
Bot utterance 'BotUttered(text: Hi there beautiful :), data: {
  "elements": null,
  "buttons": null,
  "attachment": null
})'
Current tracker state [{'prev_utter_greet': 1.0, 'intent_greet': 1.0}, {'intent_greet': 1.0, 'prev_action_listen': 1.0}, {'prev_utter_greet': 1.0, 'intent_greet': 1.0}, {'intent_ask_faq_car_loan': 1.0, 'prev_action_listen': 1.0}, {'prev_utter_greet': 1.0, 'intent_ask_faq_car_loan': 1.0}]
There is no memorised next action
Feature 'intent_ask_faq_car_loan' could not be found in feature map.
Feature 'intent_ask_faq_car_loan' could not be found in feature map.
Predicted next action using policy_1_EmbeddingPolicy
Predicted next action 'action_listen' with prob 0.74.
Action 'action_listen' ended with events '[]'
Recreating tracker for id 'default'
Received user message 'car loan' with intent '{'name': 'ask_faq_car_loan', 'confidence': 0.9618583917617798}' and entities '[]'
Logged UserUtterance - tracker now has 14 events
Current slot values: 

Current tracker state [{'intent_greet': 1.0, 'prev_action_listen': 1.0}, {'prev_utter_greet': 1.0, 'intent_greet': 1.0}, {'intent_ask_faq_car_loan': 1.0, 'prev_action_listen': 1.0}, {'prev_utter_greet': 1.0, 'intent_ask_faq_car_loan': 1.0}, {'intent_ask_faq_car_loan': 1.0, 'prev_action_listen': 1.0}]
There is no memorised next action
Feature 'intent_ask_faq_car_loan' could not be found in feature map.
Feature 'intent_ask_faq_car_loan' could not be found in feature map.
Feature 'intent_ask_faq_car_loan' could not be found in feature map.
Predicted next action using policy_1_EmbeddingPolicy
Predicted next action 'utter_greet' with prob 0.84.
Action 'utter_greet' ended with events '[]'
Bot utterance 'BotUttered(text: Hello! How can i help?, data: {
  "elements": null,
  "buttons": null,
  "attachment": null
})'
Current tracker state [{'prev_utter_greet': 1.0, 'intent_greet': 1.0}, {'intent_ask_faq_car_loan': 1.0, 'prev_action_listen': 1.0}, {'prev_utter_greet': 1.0, 'intent_ask_faq_car_loan': 1.0}, {'intent_ask_faq_car_loan': 1.0, 'prev_action_listen': 1.0}, {'prev_utter_greet': 1.0, 'intent_ask_faq_car_loan': 1.0}]
There is no memorised next action
Feature 'intent_ask_faq_car_loan' could not be found in feature map.
Feature 'intent_ask_faq_car_loan' could not be found in feature map.
Feature 'intent_ask_faq_car_loan' could not be found in feature map.
Feature 'intent_ask_faq_car_loan' could not be found in feature map.
Predicted next action using policy_1_EmbeddingPolicy
Predicted next action 'action_listen' with prob 0.81.
Action 'action_listen' ended with events '[]'
Recreating tracker for id 'default'
Received user message 'car loan' with intent '{'name': 'ask_faq_car_loan', 'confidence': 0.9618583917617798}' and entities '[]'
Logged UserUtterance - tracker now has 18 events
Current slot values: 

Current tracker state [{'intent_ask_faq_car_loan': 1.0, 'prev_action_listen': 1.0}, {'prev_utter_greet': 1.0, 'intent_ask_faq_car_loan': 1.0}, {'intent_ask_faq_car_loan': 1.0, 'prev_action_listen': 1.0}, {'prev_utter_greet': 1.0, 'intent_ask_faq_car_loan': 1.0}, {'intent_ask_faq_car_loan': 1.0, 'prev_action_listen': 1.0}]
There is no memorised next action
Feature 'intent_ask_faq_car_loan' could not be found in feature map.
Feature 'intent_ask_faq_car_loan' could not be found in feature map.
Feature 'intent_ask_faq_car_loan' could not be found in feature map.
Feature 'intent_ask_faq_car_loan' could not be found in feature map.
Feature 'intent_ask_faq_car_loan' could not be found in feature map.
Predicted next action using policy_1_EmbeddingPolicy
Predicted next action 'utter_greet' with prob 0.85.
Action 'utter_greet' ended with events '[]'
Bot utterance 'BotUttered(text: Hi there beautiful :), data: {
  "elements": null,
  "buttons": null,
  "attachment": null
})'
Current tracker state [{'prev_utter_greet': 1.0, 'intent_ask_faq_car_loan': 1.0}, {'intent_ask_faq_car_loan': 1.0, 'prev_action_listen': 1.0}, {'prev_utter_greet': 1.0, 'intent_ask_faq_car_loan': 1.0}, {'intent_ask_faq_car_loan': 1.0, 'prev_action_listen': 1.0}, {'prev_utter_greet': 1.0, 'intent_ask_faq_car_loan': 1.0}]
There is no memorised next action
Feature 'intent_ask_faq_car_loan' could not be found in feature map.
Feature 'intent_ask_faq_car_loan' could not be found in feature map.
Feature 'intent_ask_faq_car_loan' could not be found in feature map.
Feature 'intent_ask_faq_car_loan' could not be found in feature map.
Feature 'intent_ask_faq_car_loan' could not be found in feature map.
Feature 'intent_ask_faq_car_loan' could not be found in feature map.
Predicted next action using policy_1_EmbeddingPolicy
Predicted next action 'action_listen' with prob 0.81.
Action 'action_listen' ended with events '[]'
Rasa process starting
Restoring parameters from models/nlu/default/Banking_bot/intent_classifier_tensorflow_embedding.ckpt
Restoring parameters from models/dialogue/policy_1_EmbeddingPolicy/tensorflow_embedding.ckpt
Available web server routes: 
static                                             GET, HEAD, OPTIONS             /static/[filename]
custom_webhook_CmdlineInput.health                 GET, HEAD, OPTIONS             /webhooks/rest/
custom_webhook_CmdlineInput.receive                POST, OPTIONS                  /webhooks/rest/webhook
Rasa Core server is up and running on http://localhost:5005
Creating a new tracker for id 'default'.
Received user message 'car loan' with intent '{'name': 'ask_faq_car_loan', 'confidence': 0.9618583917617798}' and entities '[]'
Logged UserUtterance - tracker now has 2 events
Current slot values: 

Current tracker state [None, None, None, {}, {'prev_action_listen': 1.0, 'intent_ask_faq_car_loan': 1.0}]
There is no memorised next action
Feature 'intent_ask_faq_car_loan' could not be found in feature map.
Predicted next action using policy_1_EmbeddingPolicy
Predicted next action 'action_listen' with prob 0.75.
Action 'action_listen' ended with events '[]'
Rasa process starting
Restoring parameters from models/nlu/default/Banking_bot/intent_classifier_tensorflow_embedding.ckpt
Restoring parameters from models/dialogue/policy_1_EmbeddingPolicy/tensorflow_embedding.ckpt
Available web server routes: 
static                                             GET, OPTIONS, HEAD             /static/[filename]
custom_webhook_CmdlineInput.health                 GET, OPTIONS, HEAD             /webhooks/rest/
custom_webhook_CmdlineInput.receive                POST, OPTIONS                  /webhooks/rest/webhook
Rasa Core server is up and running on http://localhost:5005
Creating a new tracker for id 'default'.
Received user message 'car loan' with intent '{'name': 'ask_faq_car_loan', 'confidence': 0.9618583917617798}' and entities '[]'
Logged UserUtterance - tracker now has 2 events
Current slot values: 

Current tracker state [None, None, None, {}, {'prev_action_listen': 1.0, 'intent_ask_faq_car_loan': 1.0}]
There is no memorised next action
Feature 'intent_ask_faq_car_loan' could not be found in feature map.
Predicted next action using policy_1_EmbeddingPolicy
Predicted next action 'action_listen' with prob 0.75.
Action 'action_listen' ended with events '[]'
